Workbook

Sheet 封面
B2: 宝兴县旺平矿业有限责任公司地块 污染土壤治理与修复项目工程费用成本测算
B5: 本次按工序重做人材机消耗量。表6.1-1只提供方量，不提供单价。台班费由柴油、折旧、司机计算。
B7: 测算成果
B8: 指标 | D8: 金额 | E8: 口径
B9: 含税工程造价 | D9: =费用汇总!E57 -> 49430389 | E9: 费用汇总
B10: 人材机直接费 | D10: =费用汇总!E52 -> 45705399 | E10: 清单合价
B11: 不含税造价 | D11: =费用汇总!E55 -> 47990669 | E11: 直接费+管理费+利润
B12: 方案工程费锚点 | D12: =费用汇总!E58 -> 57980000 | E12: 只对照，不参与组价
B13: 与锚点差额 | D13: =费用汇总!E59 -> -8549610.6 | E13: 正数=高于方案
B14: 口径
B15: 项目 | C15: 宝兴县旺平矿业有限责任公司地块污染土壤治理与修复
B16: 地点 | C16: 四川省雅安市宝兴县陇东镇
B17: 工期 | C17: 2027年7月至2028年6月，12个月
B18: 污染物 | C18: 砷(As)、锑(Sb)
B19: 范围 | C19: 仅工程费用。不含其他费525.81万元、预备费316.19万元
B20: 组价 | C20: 综合单价=工序消耗量×基础资源价。管理费5%、利润0%、增值税3%在费用汇总
B21: 运输 | C21: 15t车实载12t，189.8km一车次一台班，油耗按0.35L/km另补柴油差
B22: 清挖 | C22: 废渣180m³/台班，污染土120m³/台班，另计场内自卸

Sheet 费用汇总
A1: 费用汇总。上半是工程量×工序综合单价。下半管理费、利润、税金不进综合单价。不含方案其他费和预备费。
A2: 本表不引用表6.1-1的综合单价。工程量来自实施方案方量；单价来自工序消耗量×基础资源价。
A3: 序号 | B3: 分部 | C3: 编码 | D3: 项目名称 | E3: 工序特征 | F3: 单位 | G3: 工程量 | H3: 综合单价 | I3: 合价（元） | J3: 单价位置 | K3: 依据
A4: 1 | B4: A临建 | C4: WP01 | D4: 测量放线 | E4: 拐点、分层标高 | F4: 项 | G4: 1 | H4: =综合单价!P4 -> 13000 | I4: =G4*H4 -> 13000 | J4: 综合单价!P4 | K4: 第5.3.1.4条
A5: 2 | B5: A临建 | C5: WP02 | D5: 施工便道 | E5: 3m宽，20cm碎石+15cm混凝土 | F5: m | G5: =工程量计算!C17 -> 350 | H5: =综合单价!P7 -> 234.1987 | I5: =G5*H5 -> 81969.545 | J5: 综合单价!P7 | K5: T14
A6: 3 | B6: A临建 | C6: WP03 | D6: 车辆冲洗平台 | E6: 平台12×4×0.25m钢筋混凝土；沉淀池砖砌，不过车 | F6: 座 | G6: 1 | H6: =综合单价!P14 -> 26207.957 | I6: =G6*H6 -> 26207.957 | J6: 综合单价!P14 | K6: 按15t渣土车轮压重算，不用方案2.5万元包干
A7: 4 | B7: A临建 | C7: WP04 | D7: 截水沟 | E7: 0.3×0.4m砖沟 | F7: m | G7: =工程量计算!C18 -> 850 | H7: =综合单价!P21 -> 70.65325 | I7: =G7*H7 -> 60055.262 | J7: 综合单价!P21 | K7: T15
A8: 5 | B8: A临建 | C8: WP05 | D8: 废水调节沉淀池 | E8: 两座砖砌，不过车，不配钢筋 | F8: 项 | G8: 1 | H8: =综合单价!P27 -> 11412.9 | I8: =G8*H8 -> 11412.9 | J8: 综合单价!P27 | K8: 工序拆量，不用100万包干
A9: 6 | B9: A临建 | C9: WP06 | D9: 地面防渗 | E9: 两布一膜+15cm混凝土 | F9: m² | G9: =工程量计算!C19 -> 600 | H9: =综合单价!P35 -> 84.00995 | I9: =G9*H9 -> 50405.97 | J9: 综合单价!P35 | K9: T16
A10: 7 | B10: A临建 | C10: WP07 | D10: 施工围挡 | E10: 2m彩钢 | F10: m | G10: =工程量计算!C24 -> 420 | H10: =综合单价!P42 -> 107.0959 | I10: =G10*H10 -> 44980.278 | J10: 综合单价!P42 | K10: T21
A11: 8 | B11: A临建 | C11: WP08 | D11: 防尘网覆盖 | E11: 材料+铺设 | F11: m² | G11: =工程量计算!C25 -> 3000 | H11: =综合单价!P47 -> 3.525 | I11: =G11*H11 -> 10575 | J11: 综合单价!P47 | K11: T22
A12: 9 | B12: A临建 | C12: WP09 | D12: 办公生活板房 | E12: 安拆一次 | F12: m² | G12: =工程量计算!C26 -> 200 | H12: =综合单价!P50 -> 480.5918 | I12: =G12*H12 -> 96118.36 | J12: 综合单价!P50 | K12: T23
A13: 10 | B13: A临建 | C13: WP10 | D13: 底泥脱水棚 | E13: 彩钢屋面+轻钢骨架，只遮雨，不用夹芯板 | F13: m² | G13: =工程量计算!C27 -> 200 | H13: =综合单价!P56 -> 106.4377 | I13: =G13*H13 -> 21287.54 | J13: 综合单价!P56 | K13: T24
A14: 11 | B14: A临建 | C14: WP32 | D14: 机械进出场 | E14: 4台机械 | F14: 项 | G14: 1 | H14: =综合单价!P139 -> 12639.1 | I14: =G14*H14 -> 12639.1 | J14: 综合单价!P139 | K14: 工序
A15: 12 | B15: B支护降水 | C15: WP11 | D15: 拉森钢板桩支护 | E15: 周长×桩长，租赁3个月 | F15: m² | G15: =工程量计算!C40 -> 3780 | H15: =综合单价!P63 -> 85.1803 | I15: =G15*H15 -> 321981.53 | J15: 综合单价!P63 | K15: D09
A16: 13 | B16: B支护降水 | C16: WP12 | D16: 基坑降水井 | E16: 成井+运行 | F16: 口 | G16: =工程量计算!C22 -> 24 | H16: =综合单价!P70 -> 6579 | I16: =G16*H16 -> 157896 | J16: 综合单价!P70 | K16: T19
A17: 14 | B17: C清挖 | C17: WP13 | D17: 废渣清挖装车 | E17: 180m³/台班 | F17: m³ | G17: =工程量计算!C4 -> 43229.84 | H17: =综合单价!P78 -> 13.34043 | I17: =G17*H17 -> 576704.65 | J17: 综合单价!P78 | K17: T01
A18: 15 | B18: C清挖 | C18: WP14 | D18: 河道底泥清挖 | E18: 干式清淤，含隔水围堰和抽水 | F18: m³ | G18: =工程量计算!C5 -> 39 | H18: =综合单价!P82 -> 73.675 | I18: =G18*H18 -> 2873.325 | J18: 综合单价!P82 | K18: T02
A19: 16 | B19: C清挖 | C19: WP15 | D19: 底泥脱水 | E19: 药剂+压滤人工 | F19: m³ | G19: =工程量计算!C5 -> 39 | H19: =综合单价!P86 -> 21.110897 | I19: =G19*H19 -> 823.325 | J19: 综合单价!P86 | K19: T02
A20: 17 | B20: C清挖 | C20: WP16 | D20: 原矿料装车 | E20: 装载机 | F20: m³ | G20: =工程量计算!C6 -> 240 | H20: =综合单价!P91 -> 9.19355 | I20: =G20*H20 -> 2206.452 | J20: 综合单价!P91 | K20: T03
A21: 18 | B21: C清挖 | C21: WP17 | D21: 污染土清挖装车 | E21: 120m³/台班 | F21: m³ | G21: =工程量计算!C7 -> 31685.41 | H21: =综合单价!P95 -> 20.40164 | I21: =G21*H21 -> 646434.33 | J21: 综合单价!P95 | K21: T04
A22: 19 | B22: D外运处置 | C22: WP18 | D22: 密闭运输至水泥窑 | E22: 12t/车次，189.8km | F22: t | G22: =工程量计算!C35 -> 115953.12 | H22: =综合单价!P100 -> 134.81472 | I22: =G22*H22 -> 15632187 | J22: 综合单价!P100 | K22: D04
A23: 20 | B23: D外运处置 | C23: WP19 | D23: 水泥窑协同处置 | E23: 不含运190元/t | F23: t | G23: =工程量计算!C35 -> 115953.12 | H23: =综合单价!P104 -> 190 | I23: =G23*H23 -> 22031092 | J23: 综合单价!P104 | K23: D04
A24: 21 | B24: E回填 | C24: WP20 | D24: 外购清洁土 | E24: 到场采购 | F24: m³ | G24: =工程量计算!C37 -> 34853.951 | H24: =综合单价!P106 -> 45 | I24: =G24*H24 -> 1568427.8 | J24: 综合单价!P106 | K24: D06
A25: 22 | B25: E回填 | C25: WP21 | D25: 分层回填压实 | E25: 摊铺碾压 | F25: m³ | G25: =工程量计算!C37 -> 34853.951 | H25: =综合单价!P108 -> 9.59355 | I25: =G25*H25 -> 334373.12 | J25: 综合单价!P108 | K25: D06
A26: 23 | B26: F废水 | C26: WP22 | D26: 废水混凝沉淀运行 | E26: PAC/PAM+泵+人工 | F26: m³ | G26: =工程量计算!C36 -> 28204.27 | H26: =综合单价!P113 -> 3.470835 | I26: =G26*H26 -> 97892.367 | J26: 综合单价!P113 | K26: D05
A27: 24 | B27: F废水 | C27: WP23 | D27: 废水外运 | E27: 10m³/车 | F27: m³ | G27: =工程量计算!C36 -> 28204.27 | H27: =综合单价!P118 -> 56.8325 | I27: =G27*H27 -> 1602919.2 | J27: 综合单价!P118 | K27: D05
A28: 25 | B28: F废水 | C28: WP24 | D28: 污水厂接收 | E28: 工业污水厂接收，75元/m³，方案市场报价 | F28: m³ | G28: =工程量计算!C36 -> 28204.27 | H28: =综合单价!P121 -> 75 | I28: =G28*H28 -> 2115320.2 | J28: 综合单价!P121 | K28: D05
A29: 26 | B29: G措施 | C29: WP25 | D29: 降尘文明施工 | E29: 出土高峰60天人工+挖运期洒水45台班 | F29: 项 | G29: 1 | H29: =综合单价!P123 -> 54416.25 | I29: =G29*H29 -> 54416.25 | J29: 综合单价!P123 | K29: 工序
A30: 27 | B30: H监测 | C30: WP26 | D30: 大气监测 | E30: 外委化验 | F30: 点次 | G30: =工程量计算!C56 -> 48 | H30: =综合单价!P127 -> 750 | I30: =G30*H30 -> 36000 | J30: 综合单价!P127 | K30: T26
A31: 28 | B31: H监测 | C31: WP27 | D31: 噪声监测 | E31: 外委化验 | F31: 点次 | G31: =工程量计算!C57 -> 24 | H31: =综合单价!P129 -> 200 | I31: =G31*H31 -> 4800 | J31: 综合单价!P129 | K31: T27
A32: 29 | B32: H监测 | C32: WP28 | D32: 废水监测 | E32: 外委化验 | F32: 样 | G32: =工程量计算!C58 -> 24 | H32: =综合单价!P131 -> 300 | I32: =G32*H32 -> 7200 | J32: 综合单价!P131 | K32: T28
A33: 30 | B33: H监测 | C33: WP29 | D33: 地下水监测 | E33: 外委化验 | F33: 样 | G33: =工程量计算!C59 -> 36 | H33: =综合单价!P133 -> 1200 | I33: =G33*H33 -> 43200 | J33: 综合单价!P133 | K33: T29
A34: 31 | B34: H监测 | C34: WP30 | D34: 土壤自检 | E34: 外委化验 | F34: 样 | G34: =工程量计算!C60 -> 80 | H34: =综合单价!P135 -> 150 | I34: =G34*H34 -> 12000 | J34: 综合单价!P135 | K34: T30
A35: 32 | B35: H监测 | C35: WP31 | D35: 危废鉴别 | E35: 外委化验 | F35: 样 | G35: =工程量计算!C61 -> 8 | H35: =综合单价!P137 -> 3500 | I35: =G35*H35 -> 28000 | J35: 综合单价!P137 | K35: T31
D36: 人材机直接费合计 | I36: =SUM(I4:I35) -> 45705399
A38: 分部小计
A39: 分部 | B39: 合价（元） | C39: 占直接费
A40: A临建 | B40: =SUMIF($B$4:$B$35,A40,$I$4:$I$35) -> 428651.91 | C40: =IF($I$36=0,0,B40/$I$36) -> 0.0093785837
A41: B支护降水 | B41: =SUMIF($B$4:$B$35,A41,$I$4:$I$35) -> 479877.53 | C41: =IF($I$36=0,0,B41/$I$36) -> 0.010499362
...

Sheet 综合单价
A1: 综合单价（只含人材机）。消耗量按工序计算，单价VLOOKUP工料机。不使用投资估算包干价，不使用其他项目的综合单价。
A2: 黄底为消耗量。台班单价是工料机表的公式结果。外委仅水泥窑、外购土、监测化验，因为这三项不在现场发生人材机。
A3: 序号 | B3: 清单编码 | C3: 项目名称 | D3: 单位 | E3: 行类 | F3: 资源编码 | G3: 资源名称 | H3: 消耗单位 | I3: 消耗量 | J3: 单价 | K3: 合价 | L3: 人工 | M3: 材料 | N3: 机械 | O3: 工序说明 | P3: 综合单价
A4: 1 | B4: WP01 | C4: 测量放线 | D4: 项 | E4: 汇总 | K4: =SUM(K5:K6) -> 13000 | L4: =SUMIF(E5:E6,"人工",K5:K6) -> 13000 | M4: =SUMIF(E5:E6,"材料",K5:K6)+SUMIF(E5:E6,"外委",K5:K6) -> 0 | N4: =SUMIF(E5:E6,"机械",K5:K6) -> 0 | O4: 人材机小计，不含管理费利润税金 | P4: =K4 -> 13000
A5: 1.1 | B5: WP01 | C5: 测量放线 | D5: 项 | E5: 人工 | F5: L02 | G5: 技术工/带班 | H5: 工日 | I5: 20 | J5: =IFERROR(VLOOKUP(F5,工料机价格!$A$4:$F$36,6,FALSE()),0) -> 350 | K5: =I5*J5 -> 7000 | O5: 2名测量员×10天，放拐点、分层标高
A6: 1.2 | B6: WP01 | C6: 测量放线 | D6: 项 | E6: 人工 | F6: L01 | G6: 普通工 | H6: 工日 | I6: 20 | J6: =IFERROR(VLOOKUP(F6,工料机价格!$A$4:$F$36,6,FALSE()),0) -> 300 | K6: =I6*J6 -> 6000 | O6: 2名司尺×10天
A7: 2 | B7: WP02 | C7: 施工便道 | D7: m | E7: 汇总 | K7: =SUM(K8:K13) -> 234.1987 | L7: =SUMIF(E8:E13,"人工",K8:K13) -> 9 | M7: =SUMIF(E8:E13,"材料",K8:K13)+SUMIF(E8:E13,"外委",K8:K13) -> 213.75 | N7: =SUMIF(E8:E13,"机械",K8:K13) -> 11.4487 | O7: 人材机小计，不含管理费利润税金 | P7: =K7 -> 234.1987
A8: 2.1 | B8: WP02 | C8: 施工便道 | D8: m | E8: 人工 | F8: L01 | G8: 普通工 | H8: 工日 | I8: 0.03 | J8: =IFERROR(VLOOKUP(F8,工料机价格!$A$4:$F$36,6,FALSE()),0) -> 300 | K8: =I8*J8 -> 9 | O8: 只留泵送混凝土收面。碎石摊铺人工含在装载机作业里，不再另计
A9: 2.2 | B9: WP02 | C9: 施工便道 | D9: m | E9: 人工 | F9: L02 | G9: 技术工/带班 | H9: 工日 | I9: 0 | J9: =IFERROR(VLOOKUP(F9,工料机价格!$A$4:$F$36,6,FALSE()),0) -> 350 | K9: =I9*J9 -> 0 | O9: 停用：便道摊铺碾压的指挥含在装载机、压路机司机里
A10: 2.3 | B10: WP02 | C10: 施工便道 | D10: m | E10: 材料 | F10: AGG | G10: 级配碎石 | H10: m³ | I10: 0.75 | J10: =IFERROR(VLOOKUP(F10,工料机价格!$A$4:$F$36,6,FALSE()),0) -> 78 | K10: =I10*J10 -> 58.5 | O10: 3m×0.20m压实×松铺1.25。原0.60按压实方直接当采购方
A11: 2.4 | B11: WP02 | C11: 施工便道 | D11: m | E11: 材料 | F11: C20 | G11: C20商品混凝土 | H11: m³ | I11: 0.45 | J11: =IFERROR(VLOOKUP(F11,工料机价格!$A$4:$F$36,6,FALSE()),0) -> 345 | K11: =I11*J11 -> 155.25 | O11: 3m×0.15m面层
A12: 2.5 | B12: WP02 | C12: 施工便道 | D12: m | E12: 机械 | F12: LDR | G12: 装载机50型台班 | H12: 台班 | I12: 0.005 | J12: =IFERROR(VLOOKUP(F12,工料机价格!$A$4:$F$41,6,FALSE()),0) -> 1445.9 | K12: =I12*J12 -> 7.2295 | O12: 摊铺碎石。600m²/台班，3m宽折每米0.005。原挖机整平口径不对
A13: 2.6 | B13: WP02 | C13: 施工便道 | D13: m | E13: 机械 | F13: RL | G13: 压路机台班 | H13: 台班 | I13: 0.004 | J13: =IFERROR(VLOOKUP(F13,工料机价格!$A$4:$F$36,6,FALSE()),0) -> 1054.8 | K13: =I13*J13 -> 4.2192 | O13: 压路机碾压约750m²/台班，3m宽折每米0.004
A14: 3 | B14: WP03 | C14: 车辆冲洗平台 | D14: 座 | E14: 汇总 | K14: =SUM(K15:K20) -> 26207.957 | L14: =SUMIF(E15:E20,"人工",K15:K20) -> 5550 | M14: =SUMIF(E15:E20,"材料",K15:K20)+SUMIF(E15:E20,"外委",K15:K20) -> 20657.957 | N14: =SUMIF(E15:E20,"机械",K15:K20) -> 0 | O14: 行车平台用钢筋混凝土；侧面沉淀池用砖砌抹面，不配钢筋。 | P14: =K14 -> 26207.957
A15: 3.1 | B15: WP03 | C15: 洗车池 | D15: 座 | E15: 人工 | F15: L01 | G15: 普通工 | H15: 工日 | I15: 18.5 | J15: =IFERROR(VLOOKUP(F15,工料机价格!$A$4:$F$43,6,FALSE()),0) -> 300 | K15: =I15*J15 -> 5550 | O15: 平台浇筑8+砖池砌筑抹面6+安装2+钢筋绑扎按2个技工折2.5普工
A16: 3.2 | B16: WP03 | C16: 洗车池 | D16: 座 | E16: 材料 | F16: PITM | G16: 砖砌沉淀池体 | H16: 座 | I16: 1 | J16: =工料机价格!F44 -> 990.9 | K16: =I16*J16 -> 990.9 | O16: 4m×2m×1.2m。砖1.83千块、砂浆1.8吨，公式计价。不过车，不用钢筋混凝土
A17: 3.3 | B17: WP03 | C17: 洗车池 | D17: 座 | E17: 材料 | F17: C20 | G17: C20商品混凝土 | H17: m³ | I17: 12 | J17: =IFERROR(VLOOKUP(F17,工料机价格!$A$4:$F$43,6,FALSE()),0) -> 345 | K17: =I17*J17 -> 4140 | O17: 只算行车平台12×4×0.25。沉淀池不再浇3.5m³钢筋混凝土
A18: 3.4 | B18: WP03 | C18: 洗车池 | D18: 座 | E18: 材料 | F18: REB | G18: 螺纹钢HRB400 | H18: t | I18: 1.15 | J18: =IFERROR(VLOOKUP(F18,工料机价格!$A$4:$F$43,6,FALSE()),0) -> 3039.18 | K18: =I18*J18 -> 3495.057 | O18: 只算平台φ16@150双向。沉淀池不配钢筋
A19: 3.5 | B19: WP03 | C19: 洗车池 | D19: 座 | E19: 材料 | F19: GRT | G19: 钢格栅盖板 | H19: m² | I19: 14.4 | J19: =IFERROR(VLOOKUP(F19,工料机价格!$A$4:$F$43,6,FALSE()),0) -> 280 | K19: =I19*J19 -> 4032 | O19: 两条轮槽12m×0.6m
A20: 3.6 | B20: WP03 | C20: 洗车池 | D20: 座 | E20: 材料 | F20: WSH | G20: 高压冲洗设备 | H20: 套 | I20: 1 | J20: =IFERROR(VLOOKUP(F20,工料机价格!$A$4:$F$43,6,FALSE()),0) -> 8000 | K20: =I20*J20 -> 8000 | O20: 泵、管路、喷嘴，12个月摊销
A21: 4 | B21: WP04 | C21: 截水沟 | D21: m | E21: 汇总 | K21: =SUM(K22:K26) -> 70.65325 | L21: =SUMIF(E22:E26,"人工",K22:K26) -> 24 | M21: =SUMIF(E22:E26,"材料",K22:K26)+SUMIF(E22:E26,"外委",K22:K26) -> 42.22 | N21: =SUMIF(E22:E26,"机械",K22:K26) -> 4.43325 | O21: 人材机小计，不含管理费利润税金 | P21: =K21 -> 70.65325
A22: 4.1 | B22: WP04 | C22: 截水沟 | D22: m | E22: 人工 | F22: L01 | G22: 普通工 | H22: 工日 | I22: 0.08 | J22: =IFERROR(VLOOKUP(F22,工料机价格!$A$4:$F$36,6,FALSE()),0) -> 300 | K22: =I22*J22 -> 24 | O22: 机械挖槽后只砌沟。瓦工约12m/天。原0.28工日/m把挖槽又算进人工
A23: 4.2 | B23: WP04 | C23: 截水沟 | D23: m | E23: 材料 | F23: BRK | G23: 页岩配砖 | H23: 千块 | I23: 0.064 | J23: =IFERROR(VLOOKUP(F23,工料机价格!$A$4:$F$36,6,FALSE()),0) -> 330 | K23: =I23*J23 -> 21.12 | O23: 0.12m³砌体÷砖净体积
A24: 4.3 | B24: WP04 | C24: 截水沟 | D24: m | E24: 材料 | F24: MOR | G24: 砌筑砂浆M10 | H24: t | I24: 0.05 | J24: =IFERROR(VLOOKUP(F24,工料机价格!$A$4:$F$36,6,FALSE()),0) -> 215 | K24: =I24*J24 -> 10.75 | O24: 砌筑0.03t+内抹面0.02t。原0.04t抹面不够
A25: 4.4 | B25: WP04 | C25: 截水沟 | D25: m | E25: 材料 | F25: C20 | G25: C20商品混凝土 | H25: m³ | I25: 0.03 | J25: =IFERROR(VLOOKUP(F25,工料机价格!$A$4:$F$36,6,FALSE()),0) -> 345 | K25: =I25*J25 -> 10.35 | O25: 沟底垫层
A26: 4.5 | B26: WP04 | C26: 截水沟 | D26: m | E26: 机械 | F26: EXC | G26: 挖掘机1.0m³台班 | H26: 台班 | I26: 0.0025 | J26: =IFERROR(VLOOKUP(F26,工料机价格!$A$4:$F$36,6,FALSE()),0) -> 1773.3 | K26: =I26*J26 -> 4.43325 | O26: 沟槽0.2m³/m，挖机约400m/台班。原0.002按500m略高
A27: 5 | B27: WP05 | C27: 废水调节沉淀池 | D27: 项 | E27: 汇总 | K27: =SUM(K28:K34) -> 11412.9 | L27: =SUMIF(E28:E34,"人工",K28:K34) -> 4800 | M27: =SUMIF(E28:E34,"材料",K28:K34)+SUMIF(E28:E34,"外委",K28:K34) -> 4839.6 | N27: =SUMIF(E28:E34,"机械",K28:K34) -> 1773.3 | O27: 砖砌抹面。不过车，不用钢筋混凝土，不用模板。 | P27: =K27 -> 11412.9
A28: 5.1 | B28: WP05 | C28: 废水调节沉淀池 | D28: 项 | E28: 人工 | F28: L01 | G28: 普通工 | H28: 工日 | I28: 16 | J28: =工料机价格!F5 -> 300 | K28: =I28*J28 -> 4800 | O28: 两座砖池砌筑抹面。原30工日是浇筑钢筋混凝土
A29: 5.2 | B29: WP05 | C29: 废水调节沉淀池 | D29: 项 | E29: 人工 | F29: L02 | G29: 技术工/带班 | H29: 工日 | I29: 0 | J29: 0 | K29: =I29*J29 -> 0 | O29: 停用：没有钢筋绑扎，不需要技工带班
A30: 5.3 | B30: WP05 | C30: 废水调节沉淀池 | D30: 项 | E30: 材料 | F30: WWM | G30: 砖砌调节池体 | H30: 项 | I30: 1 | J30: =工料机价格!F46 -> 3879.6 | K30: =I30*J30 -> 3879.6 | O30: 两座6m×3m×1.5m。砖砌抹面，不用44m³混凝土
A31: 5.4 | B31: WP05 | C31: 废水调节沉淀池 | D31: 项 | E31: 材料 | F31: REB | G31: 螺纹钢HRB400 | H31: t | I31: 0 | J31: 0 | K31: =I31*J31 -> 0 | O31: 停用：调节池不过车，不配钢筋
A32: 5.5 | B32: WP05 | C32: 废水调节沉淀池 | D32: 项 | E32: 材料 | F32: HDPE | G32: HDPE防渗膜1.5mm | H32: m² | I32: 80 | J32: =工料机价格!F15 -> 12 | K32: =I32*J32 -> 960 | O32: 砖池内防渗。原160m²模板是混凝土池才需要的
A33: 5.6 | B33: WP05 | C33: 废水调节沉淀池 | D33: 项 | E33: 机械 | F33: CRN | G33: 汽车吊25t台班 | H33: 台班 | I33: 0 | J33: 0 | K33: =I33*J33 -> 0 | O33: 停用：砖池不用吊模板
A34: 5.7 | B34: WP05 | C34: 废水调节沉淀池 | D34: 项 | E34: 机械 | F34: EXC | G34: 挖掘机1.0m³台班 | H34: 台班 | I34: 1 | J34: =工料机价格!F7 -> 1773.3 | K34: =I34*J34 -> 1773.3 | O34: 两座池槽开挖1台班。原1.5台班按混凝土池基坑
A35: 6 | B35: WP06 | C35: 地面防渗 | D35: m² | E35: 汇总 | K35: =SUM(K36:K41) -> 84.00995 | L35: =SUMIF(E36:E41,"人工",K36:K41) -> 5.9 | M35: =SUMIF(E36:E41,"材料",K36:K41)+SUMIF(E36:E41,"外委",K36:K41) -> 75.45 | N35: =SUMIF(E36:E41,"机械",K36:K41) -> 2.65995 | O35: 人材机小计，不含管理费利润税金 | P35: =K35 -> 84.00995
A36: 6.1 | B36: WP06 | C36: 地面防渗 | D36: m² | E36: 人工 | F36: L01 | G36: 普通工 | H36: 工日 | I36: 0.015 | J36: =IFERROR(VLOOKUP(F36,工料机价格!$A$4:$F$36,6,FALSE()),0) -> 300 | K36: =I36*J36 -> 4.5 | O36: 铺膜0.004+混凝土收面0.007+搭接。原0.08是手工抹灰口径
A37: 6.2 | B37: WP06 | C37: 地面防渗 | D37: m² | E37: 人工 | F37: L02 | G37: 技术工/带班 | H37: 工日 | I37: 0.004 | J37: =IFERROR(VLOOKUP(F37,工料机价格!$A$4:$F$36,6,FALSE()),0) -> 350 | K37: =I37*J37 -> 1.4 | O37: 焊接约250m2/人日
A38: 6.3 | B38: WP06 | C38: 地面防渗 | D38: m² | E38: 材料 | F38: GT | G38: 土工布400g | H38: m² | I38: 2.1 | J38: =IFERROR(VLOOKUP(F38,工料机价格!$A$4:$F$36,6,FALSE()),0) -> 5 | K38: =I38*J38 -> 10.5 | O38: 上下两层，含搭接5%
A39: 6.4 | B39: WP06 | C39: 地面防渗 | D39: m² | E39: 材料 | F39: HDPE | G39: HDPE防渗膜1.5mm | H39: m² | I39: 1.1 | J39: =IFERROR(VLOOKUP(F39,工料机价格!$A$4:$F$36,6,FALSE()),0) -> 12 | K39: =I39*J39 -> 13.2 | O39: 含搭接
A40: 6.5 | B40: WP06 | C40: 地面防渗 | D40: m² | E40: 材料 | F40: C20 | G40: C20商品混凝土 | H40: m³ | I40: 0.15 | J40: =IFERROR(VLOOKUP(F40,工料机价格!$A$4:$F$36,6,FALSE()),0) -> 345 | K40: =I40*J40 -> 51.75 | O40: 15cm面层，不是20cm估算口径
...

Sheet 工料机价格
A1: 基础资源单价（F列黄底蓝字）。台班费在本表用折旧+柴油+人工公式计算，不直接填别的项目台班价。管理费、利润、税金不在本表。
A2: 柴油用乐山2026年7月信息价6.37元/L。台班费=折旧摊销+柴油×油耗+司机。司机已含在台班费内，清单里不再另加司机工日。水泥窑190元/t为用户确认的外委价，不是人材机拆分。
A3: 编码 | B3: 类别 | C3: 名称 | D3: 规格/计算式 | E3: 单位 | F3: 不含税单价（元） | G3: 来源 | H3: 备注
A4: DIE | B4: 材料 | C4: 0号柴油 | D4: 乐山信息价 | E4: L | F4: 6.37 | G4: 柴油-综合-元-L | H4: 乐山2026年7月不含税
A5: L01 | B5: 人工 | C5: 普通工 | D5: 清底砌筑铺装巡井 | E5: 工日 | F5: 300 | G5: 普通工-太化建安-工日 | H5: 成本库
A6: L02 | B6: 人工 | C6: 技术工/带班 | D6: 测量焊接指挥 | E6: 工日 | F6: 350 | G6: 技工（大工/师傅）日工资 | H6: 成本库
A7: EXC | B7: 机械 | C7: 挖掘机1.0m³台班 | D7: 折旧900+柴油×90L+司机 | E7: 台班 | F7: =900+F4*90+F5 -> 1773.3 | G7: 台班公式 | H7: 油耗90L/台班
A8: LDR | B8: 机械 | C8: 装载机50型台班 | D8: 折旧700+柴油×70L+司机 | E8: 台班 | F8: =700+F4*70+F5 -> 1445.9 | G8: 台班公式 | H8: 油耗70L/台班
A9: DMP | B9: 机械 | C9: 自卸汽车15t台班 | D9: 折旧550+柴油×45L+司机 | E9: 台班 | F9: =550+F4*45+F5 -> 1136.65 | G9: 台班公式 | H9: 场内倒运
A10: RL | B10: 机械 | C10: 压路机台班 | D10: 折旧500+柴油×40L+司机 | E10: 台班 | F10: =500+F4*40+F5 -> 1054.8 | G10: 台班公式 | H10: 油耗40L/台班
A11: CRN | B11: 机械 | C11: 汽车吊25t台班 | D11: 折旧1200+柴油×35L+技工 | E11: 台班 | F11: =1200+F4*35+F6 -> 1772.95 | G11: 台班公式 | H11: 油耗35L/台班
A12: VIB | B12: 机械 | C12: 振动锤台班 | D12: 折旧800+柴油×50L | E12: 台班 | F12: =800+F4*50 -> 1118.5 | G12: 台班公式 | H12: 司机含在吊车
A13: WP | B13: 机械 | C13: 潜水泵7.5kW台班 | D13: 折旧40+电0.89×7.5×6h | E13: 台班 | F13: =40+0.89*7.5*6 -> 80.05 | G13: 台班公式 | H13: 乐山电价0.89元/kWh
A14: C20 | B14: 材料 | C14: C20商品混凝土 | D14: 泵送到场 | E14: m³ | F14: 345 | G14: 商品混凝土C30减20 | H14: 库内C30=365
A15: HDPE | B15: 材料 | C15: HDPE防渗膜1.5mm | D15: 双光面 | E15: m² | F15: 12 | G15: hdpe防渗膜-1-5mm双光面 | H15: 成本库
A16: GT | B16: 材料 | C16: 土工布400g | D16: 非织造 | E16: m² | F16: 5 | G16: 非织造土工布-400g | H16: 成本库
A17: REB | B17: 材料 | C17: 螺纹钢HRB400 | D17: 乐山ф16 | E17: t | F17: 3039.18 | G17: 热轧带肋钢筋-ф16 HRB400E | H17: 乐山2026年7月
A18: BRK | B18: 材料 | C18: 页岩配砖 | D18: 200×95×53 | E18: 千块 | F18: 330 | G18: 页岩配砖-200×95×53 | H18: 重庆2026年6月
A19: MOR | B19: 材料 | C19: 砌筑砂浆M10 | D19: 预拌 | E19: t | F19: 215 | G19: 砌筑砂浆 | H19: 成本库
A20: AGG | B20: 材料 | C20: 级配碎石 | D20: 便道基层到场 | E20: m³ | F20: 78 | G20: 估价 | H20: 雅安到场，库内无碎石
A21: CSP | B21: 材料 | C21: 彩钢板 | D21: 0.5mm含檩条 | E21: m² | F21: 32 | G21: 估价 | H21: 卷材折算+配件
A22: NET | B22: 材料 | C22: 防尘网 | D22: 6针，只计材料 | E22: m² | F22: 2.5 | G22: 估价 | H22: 不含铺设综合价
A23: LAS | B23: 材料 | C23: 拉森钢板桩租赁 | D23: SP-U400月租 | E23: t·月 | F23: 180 | G23: 估价 | H23: 库内无租赁价
A24: PIPE | B24: 材料 | C24: 降水井管 | D24: φ300含滤水管 | E24: m | F24: 85 | G24: 估价 | H24: 库内无井管价
A25: PAC | B25: 材料 | C25: 聚合氯化铝PAC | D25: 混凝 | E25: t | F25: 1100 | G25: 聚合氯化铝PAC-元-t | H25: 成本库
... A35: SOILT | B35: 外委 | C35: 土壤检测外委 | D35: 砷、锑 | E35: 样 | F35: 150 | G35: 检测外委费-土壤水气危废 | H35: 成本库
A36: RATE | B36: 机械 | C36: 密闭运输吨公里单价 | D36: 往返油0.64L/km÷实载12t×柴油 | E36: 元/t·km | F36: =0.64*F4/12 -> 0.33973333 | G36: 按距离 | H36: 只含随距离增加的油耗
A37: HW | B37: 外委 | C37: 危险特性鉴别 | D37: 全项 | E37: 样 | F37: 3500 | G37: 百锦路-危险特性鉴别全项 | H37: 成本库
A38: PLY | B38: 材料 | C38: 胶合板模板 | D38: 2440×1220×9，周转3次摊销 | E38: m² | F38: 5.9333333 | G38: 胶合板-2440×1220×9 | H38: 买价17.8，周转3次
A39: BRD | B39: 材料 | C39: 岩棉夹芯板 | D39: 活动房墙屋，按展开面积 | E39: m² | F39: 180 | G39: 由岩棉夹芯板活动房980元/m²建筑面积拆出 | H39: 不含地面和人工。不用彩钢32元冒充
A40: RIG | B40: 机械 | C40: 降水钻机台班 | D40: 折旧2500+柴油×60L+司机 | E40: 台班 | F40: =2500+F4*60+F5 -> 3182.2 | G40: 台班公式 | H40: 卵石层成井。挖机不能成井
A41: SPR | B41: 机械 | C41: 洒水车台班 | D41: 折旧350+柴油×25L+司机 | E41: 台班 | F41: =350+F4*25+F5 -> 809.25 | G41: 台班公式 | H41: 不用15t渣土车台班代替
A42: GRT | B42: 材料 | C42: 钢格栅盖板 | D42: 重型车行 | E42: m² | F42: 280 | G42: 估价 | H42: 库内无格栅。槽钢格栅280元/m²
A43: WSH | B43: 材料 | C43: 高压冲洗设备 | D43: 泵、管路、喷嘴，摊销 | E43: 套 | F43: 8000 | G43: 估价 | H43: 购置约2.4万，12个月摊销1/3
A44: PITM | B44: 材料 | C44: 砖砌沉淀池体 | D44: 砖1.83千块+砂浆1.8t | E44: 座 | F44: =1.83*F18+1.8*F19 -> 990.9 | G44: 砖+砂浆公式 | H44: 侧池不过车，不配钢筋，不用混凝土
A45: RHS | B45: 材料 | C45: 轻钢方管骨架 | D45: 临时棚柱梁檩条 | E45: t | F45: =3400 -> 3400 | G45: 乐山方钢信息价约3338元/t上浮 | H45: 不用钢筋冒充，也不用夹芯板含骨架
A46: WWM | B46: 材料 | C46: 砖砌调节池体 | D46: 两座，砖6.87千块+砂浆7.5t | E46: 项 | F46: =6.87*F18+7.5*F19 -> 3879.6 | G46: 砖+砂浆 | H46: 不过车，不配钢筋，不用模板
A47: BAG | B47: 材料 | C47: 编织袋 | D47: 装土围堰 | E47: 条 | F47: 0.8 | G47: 估价 | H47: 库内无编织袋价
A48: DRY | B48: 材料 | C48: 底泥干挖措施 | D48: 编织袋200条+排水泵0.5台班 | E48: 项 | F48: =200*F47+0.5*F13 -> 200.025 | G48: 袋+泵 | H48: 隔水围堰和抽水，不含挖机
A49: CHN | B49: 材料 | C49: 槽钢围檩租赁 | D49: Q235B 16-22#，3个月 | E49: t·月 | F49: 70 | G49: 由槽钢买价3284.96元/t折月租 | H49: 拉森不用螺纹钢。围檩租赁，不买断
...

Sheet 工程量计算
A1: 工程量计算。黄底为输入，绿底为公式。表6.1-1只提供方量、吨位和运距，不提供单价。
A2: 废渣清挖以表6.1-1的43229.84 m³为准。污染土以表5.3-3的31685.41 m³为准。支护周长、降水井、便道结构为方案未给的施工假设。
A3: 编码 | B3: 名称 | C3: 数值 | D3: 单位 | E3: 公式/口径 | F3: 来源 | G3: 去向 | H3: 备注
A4: T01 | B4: 废渣清挖方量 | C4: 43229.84 | D4: m³ | E4: 输入 | F4: 表6.1-1 | G4: 清挖 | H4: Ⅱ类一般工业固废
A5: T02 | B5: 河道底泥方量 | C5: 39 | D5: m³ | E5: 输入 | F5: 表6.1-1 | G5: 清挖 | H5: 干式清淤
A6: T03 | B6: 原矿料方量 | C6: 240 | D6: m³ | E6: 输入 | F6: 表6.1-1 | G6: 清挖 | H6: 其他工业固废
A7: T04 | B7: 污染土方量 | C7: 31685.41 | D7: m³ | E7: 输入 | F7: 表5.3-3 | G7: 清挖 | H7: 砷、锑
A8: T05 | B8: 废渣密度 | C8: 1.5 | D8: t/m³ | E8: 输入 | F8: 第5.3.2.1条 | G8: 吨位
A9: T06 | B9: 底泥预处理后重量 | C9: 32.5 | D9: t | E9: 输入 | F9: 第5.3.2.1条 | G9: 外运 | H9: 含水率降至50%
A10: T07 | B10: 原矿料密度 | C10: 1.58 | D10: t/m³ | E10: 输入 | F10: 表6.1-1备注 | G10: 吨位
A11: T08 | B11: 污染土容重 | C11: 1.6 | D11: t/m³ | E11: 输入 | F11: 第5.3.2.1条 | G11: 吨位
A12: T09 | B12: 水泥窑运距 | C12: 189.8 | D12: km | E12: 输入 | F12: 第5.3.2.2条乐山诺聚 | G12: 运输 | H12: 运费单列
A13: T10 | B13: 清洁土增容比 | C13: 1.1 | D13: - | E13: 输入 | F13: 表6.1-1口径 | G13: 回填 | H13: 只回补污染土坑
A14: T11 | B14: 遗留废水 | C14: 281 | D14: m³ | E14: 输入 | F14: 第1.1条 | G14: 废水
A15: T12 | B15: 基坑废水 | C15: 27916.77 | D15: m³ | E15: 输入 | F15: 表6.1-1 | G15: 废水
A16: T13 | B16: 底泥余水 | C16: 6.5 | D16: m³ | E16: 输入 | F16: 表6.1-1 | G16: 废水
A17: T14 | B17: 施工便道长度 | C17: 350 | D17: m | E17: 输入 | F17: 表6.1-1 | G17: 临建 | H17: 宽3m
A18: T15 | B18: 截水沟长度 | C18: 850 | D18: m | E18: 输入 | F18: 表6.1-1 | G18: 临建 | H18: 0.3×0.4m砖沟
A19: T16 | B19: 防渗面积 | C19: 600 | D19: m² | E19: 输入 | F19: 表6.1-1 | G19: 临建 | H19: 两布一膜+15cm
A20: T17 | B20: 基坑临边周长 | C20: 420 | D20: m | E20: 输入 | F20: 估价 | G20: 支护 | H20: 方案未给周长
A21: T18 | B21: 拉森桩长 | C21: 9 | D21: m | E21: 输入 | F21: 估价 | G21: 支护 | H21: 覆盖最大挖深7.5m
A22: T19 | B22: 降水井数量 | C22: 24 | D22: 口 | E22: 输入 | F22: 估价 | G22: 降水 | H22: 临河侧间距5m
A23: T20 | B23: 降水井深 | C23: 12 | D23: m | E23: 输入 | F23: 估价 | G23: 降水
A24: T21 | B24: 围挡长度 | C24: 420 | D24: m | E24: 输入 | F24: 估价 | G24: 临建
A25: T22 | B25: 防尘网面积 | C25: 3000 | D25: m² | E25: 输入 | F25: 估价 | G25: 临建
A26: T23 | B26: 办公板房面积 | C26: 200 | D26: m² | E26: 输入 | F26: 估价 | G26: 临建 | H26: 12个月只计一次安拆
A27: T24 | B27: 底泥棚面积 | C27: 200 | D27: m² | E27: 输入 | F27: 估价 | G27: 临建 | H27: 20×10m
A28: T25 | B28: 方案工程费锚点 | C28: 5798 | D28: 万元 | E28: 输入 | F28: 表6.1-1 | G28: 对照 | H28: 不参与组价
A30: 派生量
A31: 编码 | B31: 名称 | C31: 数值 | D31: 单位 | E31: 公式/口径 | F31: 来源 | G31: 去向 | H31: 备注
A32: D01 | B32: 废渣吨位 | C32: =C4*C8 -> 64844.76 | D32: t | E32: T01×密度 | F32: 应≈64844.76 | G32: 外运
A33: D02 | B33: 原矿料吨位 | C33: =C6*C10 -> 379.2 | D33: t | E33: T03×密度 | F33: 应≈379.20 | G33: 外运
A34: D03 | B34: 污染土吨位 | C34: =C7*C11 -> 50696.656 | D34: t | E34: T04×容重 | F34: 应≈50696.66 | G34: 外运
A35: D04 | B35: 外运合计 | C35: =C32+C9+C33+C34 -> 115953.12 | D35: t | E35: 废渣+底泥+原矿料+污染土 | F35: 应≈115953.12 | G35: 运输/窑
A36: D05 | B36: 废水合计 | C36: =C14+C15+C16 -> 28204.27 | D36: m³ | E36: 三类废水 | F36: 应≈28204.27 | G36: 处理
A37: D06 | B37: 外购清洁土 | C37: =C7*C13 -> 34853.951 | D37: m³ | E37: 污染土×1.1 | F37: 应≈34853.95 | G37: 回填
A38: D07 | B38: 清挖总量 | C38: =C4+C5+C6+C7 -> 75194.25 | D38: m³ | E38: 四类实方 | G38: 校核
A39: D08 | B39: 便道面积 | C39: =C17*3 -> 1050 | D39: m² | E39: 长×3m | G39: WP02
A40: D09 | B40: 拉森面积 | C40: =C20*C21 -> 3780 | D40: m² | E40: 周长×桩长 | G40: WP11
A41: D10 | B41: 拉森吨位 | C41: =C40*0.075 -> 283.5 | D41: t | E41: 面积×75kg/m | F41: SP-U400 | G41: 租赁
...
